Workbook

Sheet Resumen
A1: Pixeles y ad tech instalados — Top 100 eCommerce México × LSIX
A2: Vendors agregados por solicitud (21-ago): Ogury, Quantcast, Smarterclick, Acuity Ads/illumin, AppNexus, Google Dynamic Remarketing (Taboola y Xandr ya estaban). Método: (1) navegador headless Chromium capturando todas las requests de red de la home (equivalente a Ghostery), ~10s + scroll; (2) HTML + contenedores GTM. Solo home page: pixeles que disparan únicamente en checkout/thank-you pueden no aparecer. Fecha: 21-ago-2026.
A4: Sitios escaneados | B4: 100
A5: Con lectura válida | B5: =B4-B6 -> 76
A6: Bloqueados (pendiente Chrome/Ghostery) | B6: =COUNTIF(Matriz_Pixeles!F3:F102,"BLOQUEADO*") -> 24
A8: Vendor / pixel | B8: Categoría | C8: # sitios | D8: % de sitios con lectura
A9: Google Ads / gtag | B9: Paid media | C9: =SUM(Matriz_Pixeles!K3:K102) -> 57 | D9: =IF($B$5=0,0,C9/$B$5) -> 0.75
A10: Meta Pixel | B10: Paid media | C10: =SUM(Matriz_Pixeles!L3:L102) -> 48 | D10: =IF($B$5=0,0,C10/$B$5) -> 0.63157895
A11: TikTok Pixel | B11: Paid media | C11: =SUM(Matriz_Pixeles!M3:M102) -> 42 | D11: =IF($B$5=0,0,C11/$B$5) -> 0.55263158
A12: Pinterest Tag | B12: Paid media | C12: =SUM(Matriz_Pixeles!N3:N102) -> 13 | D12: =IF($B$5=0,0,C12/$B$5) -> 0.17105263
A13: Snap Pixel | B13: Paid media | C13: =SUM(Matriz_Pixeles!O3:O102) -> 1 | D13: =IF($B$5=0,0,C13/$B$5) -> 0.013157895
A14: LinkedIn Insight | B14: Paid media | C14: =SUM(Matriz_Pixeles!P3:P102) -> 6 | D14: =IF($B$5=0,0,C14/$B$5) -> 0.078947368
A15: X / Twitter Pixel | B15: Paid media | C15: =SUM(Matriz_Pixeles!Q3:Q102) -> 11 | D15: =IF($B$5=0,0,C15/$B$5) -> 0.14473684
A16: Microsoft Ads (UET) | B16: Paid media | C16: =SUM(Matriz_Pixeles!R3:R102) -> 25 | D16: =IF($B$5=0,0,C16/$B$5) -> 0.32894737
A17: Amazon Ads | B17: Paid media | C17: =SUM(Matriz_Pixeles!S3:S102) -> 7 | D17: =IF($B$5=0,0,C17/$B$5) -> 0.092105263
A18: Criteo | B18: Retargeting / CPA | C18: =SUM(Matriz_Pixeles!T3:T102) -> 11 | D18: =IF($B$5=0,0,C18/$B$5) -> 0.14473684
A19: RTB House | B19: Retargeting / CPA | C19: =SUM(Matriz_Pixeles!U3:U102) -> 20 | D19: =IF($B$5=0,0,C19/$B$5) -> 0.26315789
A20: Google Dynamic Remarketing | B20: Retargeting / CPA | C20: =SUM(Matriz_Pixeles!V3:V102) -> 23 | D20: =IF($B$5=0,0,C20/$B$5) -> 0.30263158
A21: Smarterclick | B21: Retargeting / CPA | C21: =SUM(Matriz_Pixeles!W3:W102) -> 1 | D21: =IF($B$5=0,0,C21/$B$5) -> 0.013157895
A22: Taboola | B22: Native | C22: =SUM(Matriz_Pixeles!X3:X102) -> 8 | D22: =IF($B$5=0,0,C22/$B$5) -> 0.10526316
A23: Outbrain | B23: Native | C23: =SUM(Matriz_Pixeles!Y3:Y102) -> 3 | D23: =IF($B$5=0,0,C23/$B$5) -> 0.039473684
A24: Awin | B24: Afiliados | C24: =SUM(Matriz_Pixeles!Z3:Z102) -> 16 | D24: =IF($B$5=0,0,C24/$B$5) -> 0.21052632
A25: Impact | B25: Afiliados | C25: =SUM(Matriz_Pixeles!AA3:AA102) -> 0 | D25: =IF($B$5=0,0,C25/$B$5) -> 0
A26: CJ Affiliate | B26: Afiliados | C26: =SUM(Matriz_Pixeles!AB3:AB102) -> 0 | D26: =IF($B$5=0,0,C26/$B$5) -> 0
A27: Rakuten Advertising | B27: Afiliados | C27: =SUM(Matriz_Pixeles!AC3:AC102) -> 1 | D27: =IF($B$5=0,0,C27/$B$5) -> 0.013157895
A28: Admitad | B28: Afiliados | C28: =SUM(Matriz_Pixeles!AD3:AD102) -> 10 | D28: =IF($B$5=0,0,C28/$B$5) -> 0.13157895
A29: Soicos | B29: Afiliados | C29: =SUM(Matriz_Pixeles!AE3:AE102) -> 8 | D29: =IF($B$5=0,0,C29/$B$5) -> 0.10526316
A30: Partnerize | B30: Afiliados | C30: =SUM(Matriz_Pixeles!AF3:AF102) -> 1 | D30: =IF($B$5=0,0,C30/$B$5) -> 0.013157895
A31: AppsFlyer | B31: MMP / App | C31: =SUM(Matriz_Pixeles!AG3:AG102) -> 9 | D31: =IF($B$5=0,0,C31/$B$5) -> 0.11842105
A32: Adjust | B32: MMP / App | C32: =SUM(Matriz_Pixeles!AH3:AH102) -> 2 | D32: =IF($B$5=0,0,C32/$B$5) -> 0.026315789
A33: Branch | B33: MMP / App | C33: =SUM(Matriz_Pixeles!AI3:AI102) -> 0 | D33: =IF($B$5=0,0,C33/$B$5) -> 0
A34: Kochava | B34: MMP / App | C34: =SUM(Matriz_Pixeles!AJ3:AJ102) -> 1 | D34: =IF($B$5=0,0,C34/$B$5) -> 0.013157895
A35: Singular | B35: MMP / App | C35: =SUM(Matriz_Pixeles!AK3:AK102) -> 6 | D35: =IF($B$5=0,0,C35/$B$5) -> 0.078947368
A36: DoubleClick Floodlight / DV360 / CM360 | B36: Programmatic (Google) | C36: =SUM(Matriz_Pixeles!AL3:AL102) -> 48 | D36: =IF($B$5=0,0,C36/$B$5) -> 0.63157895
A37: Adform | B37: Programmatic | C37: =SUM(Matriz_Pixeles!AM3:AM102) -> 3 | D37: =IF($B$5=0,0,C37/$B$5) -> 0.039473684
A38: Xandr / AppNexus | B38: Programmatic | C38: =SUM(Matriz_Pixeles!AN3:AN102) -> 5 | D38: =IF($B$5=0,0,C38/$B$5) -> 0.065789474
A39: The Trade Desk | B39: Programmatic | C39: =SUM(Matriz_Pixeles!AO3:AO102) -> 6 | D39: =IF($B$5=0,0,C39/$B$5) -> 0.078947368
A40: Ogury | B40: Programmatic | C40: =SUM(Matriz_Pixeles!AP3:AP102) -> 1 | D40: =IF($B$5=0,0,C40/$B$5) -> 0.013157895
A41: Acuity Ads / illumin | B41: Programmatic | C41: =SUM(Matriz_Pixeles!AQ3:AQ102) -> 1 | D41: =IF($B$5=0,0,C41/$B$5) -> 0.013157895
A42: AppNexus (Xandr legacy) | B42: Programmatic | C42: =SUM(Matriz_Pixeles!AR3:AR102) -> 5 | D42: =IF($B$5=0,0,C42/$B$5) -> 0.065789474
...

Sheet Matriz_Pixeles
K1: Paid media | L1: Paid media | M1: Paid media | N1: Paid media | O1: Paid media | P1: Paid media | Q1: Paid media | R1: Paid media | S1: Paid media | T1: Retargeting / CPA | U1: Retargeting / CPA | V1: Retargeting / CPA | W1: Retargeting / CPA | X1: Native | Y1: Native | Z1: Afiliados | AA1: Afiliados | AB1: Afiliados | AC1: Afiliados | AD1: Afiliados | AE1: Afiliados | AF1: Afiliados | AG1: MMP / App | AH1: MMP / App | AI1: MMP / App | AJ1: MMP / App | AK1: MMP / App | AL1: Programmatic (Google) | AM1: Programmatic | AN1: Programmatic | AO1: Programmatic | AP1: Programmatic | AQ1: Programmatic | AR1: Programmatic | AS1: Programmatic | AT1: Programmatic | AU1: Contextual | AV1: Video/Native | AW1: Data / DMP | AX1: Data / DMP | AY1: Data / DMP | AZ1: Data / DMP | BA1: Data / DMP | BB1: Identity | BC1: Identity | BD1: Tag mgmt | BE1: Tag mgmt | BF1: Analytics | BG1: Analytics | BH1: CDP | BI1: UX | BJ1: UX | BK1: UX | BL1: UX | BM1: Martech / CRM | BN1: Martech / CRM | BO1: Martech / CRM | BP1: Martech / CRM | BQ1: Martech / CRM | BR1: Martech / CRM | BS1: Martech / CRM | BT1: Martech / CRM | BU1: Martech / CRM | BV1: Martech / CRM | BW1: Personalización | BX1: Personalización | BY1: Search | BZ1: Reviews | CA1: Reviews | CB1: Chat | CC1: Chat | CD1: Plataforma | CE1: Plataforma | CF1: Plataforma | CG1: Plataforma | CH1: Plataforma | CI1: Infra | CJ1: Infra
A2: # | B2: Empresa | C2: Dominio | D2: Categoría | E2: En CRM | F2: Estatus scan | G2: Método | H2: # trackers | I2: GTM IDs | J2: Señal CPA / fit LSIX | K2: Google Ads / gtag | L2: Meta Pixel | M2: TikTok Pixel | N2: Pinterest Tag | O2: Snap Pixel | P2: LinkedIn Insight | Q2: X / Twitter Pixel | R2: Microsoft Ads (UET) | S2: Amazon Ads | T2: Criteo | U2: RTB House | V2: Google Dynamic Remarketing | W2: Smarterclick | X2: Taboola | Y2: Outbrain | Z2: Awin | AA2: Impact | AB2: CJ Affiliate | AC2: Rakuten Advertising | AD2: Admitad | AE2: Soicos | AF2: Partnerize | AG2: AppsFlyer | AH2: Adjust | AI2: Branch | AJ2: Kochava | AK2: Singular | AL2: DoubleClick Floodlight / DV360 / CM360 | AM2: Adform | AN2: Xandr / AppNexus | AO2: The Trade Desk | AP2: Ogury | AQ2: Acuity Ads / illumin | AR2: AppNexus (Xandr legacy) | AS2: MediaMath | AT2: Yahoo DSP | AU2: Seedtag | AV2: Teads | AW2: Quantcast | AX2: Retargetly | AY2: Lotame | AZ2: Oracle BlueKai | BA2: Adobe Audience Manager | BB2: LiveRamp | BC2: ID5 | BD2: Google Tag Manager | BE2: Tealium | BF2: GA4 | BG2: Adobe Analytics | BH2: Segment | BI2: Hotjar | BJ2: Microsoft Clarity | BK2: Contentsquare | BL2: FullStory | BM2: Insider | BN2: Emarsys (SAP) | BO2: Salesforce Marketing Cloud | BP2: Braze | BQ2: CleverTap | BR2: MoEngage | BS2: Klaviyo | BT2: HubSpot | BU2: Connectif | BV2: Bloomreach | BW2: Dynamic Yield | BX2: Retail Rocket | BY2: Algolia | BZ2: Bazaarvoice | CA2: Yotpo | CB2: Zendesk | CC2: Intercom | CD2: Shopify | CE2: VTEX | CF2: Salesforce Commerce Cloud | CG2: Adobe Commerce (Magento) | CH2: SAP Commerce | CI2: Akamai | CJ2: Cloudflare
A3: 1 | B3: Mercado Libre | C3: mercadolibre.com.mx | D3: Marketplace | E3: Sí | F3: HTTP 200 | G3: Red (navegador) + HTML/GTM | H3: 3 | BF3: 1 | BI3: 1 | BK3: 1
A4: 2 | B4: Amazon México | C4: amazon.com.mx | D4: Marketplace | E4: Sí | F4: HTTP 202 | G4: HTML/GTM | H4: 1 | BK4: 1
A5: 3 | B5: Temu | C5: temu.com | D5: Marketplace | E5: No | F5: HTTP 200 | G5: HTML/GTM | H5: 3 | J5: Native/performance | K5: 1 | X5: 1 | BF5: 1
A6: 4 | B6: AliExpress | C6: aliexpress.com | D6: Marketplace | E6: No | F6: BLOQUEADO · revisar en Chrome/Ghostery | H6: 0
A7: 5 | B7: Shein | C7: shein.com.mx | D7: Marketplace | E7: No | F7: HTTP 200 | G7: HTML/GTM | H7: 7 | J7: Programa de afiliados activo (ya paga CPA) | K7: 1 | Z7: 1 | AD7: 1 | BF7: 1 | BN7: 1 | BT7: 1 | CB7: 1
A8: 6 | B8: Claro Shop (Grupo Carso) | C8: claroshop.com | D8: Marketplace | E8: No | F8: HTTP 200 | G8: Red (navegador) + HTML/GTM | H8: 16 | I8: GTM-K7PM8MQ | J8: Retargeting a CPA/CPC (RTB House/Criteo/Smarterclick) · MMP instalado (atribución app lista) · Native/performance | K8: 1 | L8: 1 | M8: 1 | U8: 1 | X8: 1 | AK8: 1 | AL8: 1 | AN8: 1 | AR8: 1 | AZ8: 1 | BD8: 1 | BF8: 1 | BI8: 1 | BN8: 1 | BY8: 1 | CA8: 1
A9: 7 | B9: Liverpool | C9: liverpool.com.mx | D9: Departamental | E9: Sí | F9: HTTP 403 · bloqueo bot (revisar en Chrome/Ghostery) | G9: HTML/GTM | H9: 10 | I9: GTM-KM2VZFW | J9: Retargeting a CPA/CPC (RTB House/Criteo/Smarterclick) · MMP instalado (atribución app lista) | K9: 1 | M9: 1 | R9: 1 | U9: 1 | AG9: 1 | AL9: 1 | BD9: 1 | BF9: 1 | BO9: 1 | BZ9: 1
A10: 8 | B10: Suburbia | C10: suburbia.com.mx | D10: Departamental | E10: No | F10: HTTP 200 | G10: Red (navegador) + HTML/GTM | H10: 12 | I10: GTM-KM2VZFW, GTM-P99XGLW | J10: Retargeting a CPA/CPC (RTB House/Criteo/Smarterclick) · MMP instalado (atribución app lista) | K10: 1 | L10: 1 | M10: 1 | N10: 1 | R10: 1 | U10: 1 | AG10: 1 | AL10: 1 | BD10: 1 | BF10: 1 | BO10: 1 | BZ10: 1
A11: 9 | B11: El Palacio de Hierro | C11: elpalaciodehierro.com | D11: Departamental | E11: No | F11: HTTP 200 | G11: Red (navegador) + HTML/GTM | H11: 18 | I11: GTM-S9GP | J11: Retargeting a CPA/CPC (RTB House/Criteo/Smarterclick) · Dynamic remarketing Google activo · Programa de afiliados activo (ya paga CPA) · MMP instalado (atribución app lista) | K11: 1 | L11: 1 | M11: 1 | N11: 1 | U11: 1 | V11: 1 | AE11: 1 | AG11: 1 | AL11: 1 | BD11: 1 | BF11: 1 | BK11: 1 | BM11: 1 | BO11: 1 | BT11: 1 | BZ11: 1 | CF11: 1 | CJ11: 1
A12: 10 | B12: Sears México (Grupo Carso) | C12: sears.com.mx | D12: Departamental | E12: No | F12: BLOQUEADO · revisar en Chrome/Ghostery | H12: 0
A13: 11 | B13: Sanborns | C13: sanborns.com.mx | D13: Departamental | E13: No | F13: BLOQUEADO · revisar en Chrome/Ghostery | H13: 0
A14: 12 | B14: Coppel | C14: coppel.com | D14: Departamental | E14: Sí | F14: HTTP 200 | G14: Red (navegador) | H14: 3 | I14: GTM-MLFDXSFC, GTM-MQC5RG5C, GTM-NL3WNDZV, GTM-NVKCT9W5, GTM-NXQMNBJG, GTM-P3VZMZXT, GTM-T58P8MMW, GTM-TD6ZZHT4, GTM-WTBN8XVR | BD14: 1 | BF14: 1 | BN14: 1
A15: 13 | B15: Elektra | C15: elektra.mx | D15: Departamental | E15: Sí | F15: HTTP 200 | G15: Red (navegador) + HTML/GTM | H15: 21 | I15: GTM-P7K53B9 | J15: Dynamic remarketing Google activo · Programa de afiliados activo (ya paga CPA) · MMP instalado (atribución app lista) | K15: 1 | L15: 1 | M15: 1 | N15: 1 | R15: 1 | V15: 1 | Z15: 1 | AE15: 1 | AG15: 1 | AL15: 1 | AN15: 1 | AR15: 1 | BA15: 1 | BD15: 1 | BE15: 1 | BF15: 1 | BG15: 1 | BN15: 1 | CC15: 1 | CE15: 1 | CJ15: 1
A16: 14 | B16: Walmart de México | C16: walmart.com.mx | D16: Autoservicio / Grocery | E16: Sí | F16: BLOQUEADO · revisar en Chrome/Ghostery | H16: 0
A17: 15 | B17: Bodega Aurrera | C17: bodegaaurrera.com.mx | D17: Autoservicio / Grocery | E17: Sí | F17: HTTP 200 · bloqueo bot (revisar en Chrome/Ghostery) | G17: Red (navegador) + HTML/GTM | H17: 3 | BA17: 1 | BF17: 1 | BG17: 1
A18: 16 | B18: Sam's Club México | C18: sams.com.mx | D18: Autoservicio / Grocery | E18: No | F18: HTTP 200 · bloqueo bot (revisar en Chrome/Ghostery) | G18: Red (navegador) + HTML/GTM | H18: 3 | BA18: 1 | BF18: 1 | BG18: 1
A19: 17 | B19: Costco México | C19: costco.com.mx | D19: Autoservicio / Grocery | E19: No | F19: HTTP 200 | G19: Red (navegador) + HTML/GTM | H19: 5 | I19: GTM-PVSS4SK | K19: 1 | AL19: 1 | BD19: 1 | BF19: 1 | BZ19: 1
A20: 18 | B20: Soriana | C20: soriana.com | D20: Autoservicio / Grocery | E20: Sí | F20: HTTP 403 · bloqueo bot (revisar en Chrome/Ghostery) | G20: Red (navegador) + HTML/GTM | H20: 2 | BF20: 1 | CJ20: 1
A21: 19 | B21: Chedraui | C21: chedraui.com.mx | D21: Autoservicio / Grocery | E21: Sí | F21: BLOQUEADO · revisar en Chrome/Ghostery | H21: 0
A22: 20 | B22: La Comer | C22: lacomer.com.mx | D22: Autoservicio / Grocery | E22: No | F22: BLOQUEADO · revisar en Chrome/Ghostery | H22: 0
A23: 21 | B23: HEB México | C23: heb.com.mx | D23: Autoservicio / Grocery | E23: No | F23: HTTP 200 | G23: Red (navegador) + HTML/GTM | H23: 10 | I23: GTM-MDLCJGHZ, GTM-P4HR233H | J23: MMP instalado (atribución app lista) | K23: 1 | L23: 1 | M23: 1 | R23: 1 | S23: 1 | AK23: 1 | AL23: 1 | BD23: 1 | BF23: 1 | BV23: 1
A24: 22 | B24: Rappi | C24: rappi.com.mx | D24: Delivery / QSR | E24: Sí | F24: HTTP 200 | G24: Red (navegador) + HTML/GTM | H24: 12 | I24: GTM-WJZNQMX | J24: MMP instalado (atribución app lista) | K24: 1 | L24: 1 | M24: 1 | R24: 1 | AG24: 1 | AK24: 1 | AL24: 1 | AV24: 1 | BD24: 1 | BF24: 1 | BI24: 1 | BP24: 1
A25: 23 | B25: Uber Eats México | C25: ubereats.com | D25: Delivery / QSR | E25: No | F25: HTTP 200 | G25: Red (navegador) + HTML/GTM | H25: 17 | J25: Retargeting a CPA/CPC (RTB House/Criteo/Smarterclick) · MMP instalado (atribución app lista) · Native/performance | K25: 1 | L25: 1 | M25: 1 | O25: 1 | Q25: 1 | R25: 1 | S25: 1 | T25: 1 | Y25: 1 | AK25: 1 | AO25: 1 | BE25: 1 | BF25: 1 | BG25: 1 | BJ25: 1 | CC25: 1 | CJ25: 1
A26: 24 | B26: DiDi Food México | C26: didiglobal.com | D26: Delivery / QSR | E26: No | F26: HTTP 200 | G26: Red (navegador) + HTML/GTM | H26: 3 | J26: Programa de afiliados activo (ya paga CPA) | L26: 1 | Z26: 1 | BF26: 1
A27: 25 | B27: Jüsto | C27: justo.mx | D27: Autoservicio / Grocery | E27: No | F27: HTTP 200 | G27: Red (navegador) + HTML/GTM | H27: 7 | I27: GTM-M2CF26XG | J27: Stack de data compatible con LSIX | M27: 1 | BB27: 1 | BD27: 1 | BF27: 1 | BH27: 1 | BY27: 1 | CJ27: 1
A28: 26 | B28: Alsea (Domino's / Starbucks / BK / Vips) | C28: alsea.com.mx | D28: Delivery / QSR | E28: Sí | F28: HTTP 200 | G28: Red (navegador) + HTML/GTM | H28: 2 | I28: GTM-W3FHXCVX | BD28: 1 | BF28: 1
A29: 27 | B29: McDonald's México (Arcos Dorados) | C29: mcdonalds.com.mx | D29: Delivery / QSR | E29: No | F29: HTTP 200 | G29: Red (navegador) + HTML/GTM | H29: 8 | I29: GTM-M3L33JX | K29: 1 | L29: 1 | M29: 1 | Q29: 1 | AL29: 1 | BD29: 1 | BF29: 1 | BJ29: 1
A30: 28 | B30: KFC México (Yum!) | C30: kfc.com.mx | D30: Delivery / QSR | E30: No | F30: HTTP 200 | G30: HTML/GTM | H30: 1 | BF30: 1
A31: 29 | B31: Little Caesars México | C31: littlecaesars.com.mx | D31: Delivery / QSR | E31: No | F31: HTTP 200 | G31: Red (navegador) + HTML/GTM | H31: 11 | I31: GTM-TM9J6BJ | J31: Retargeting a CPA/CPC (RTB House/Criteo/Smarterclick) · MMP instalado (atribución app lista) · Native/performance | K31: 1 | L31: 1 | Q31: 1 | S31: 1 | T31: 1 | X31: 1 | Y31: 1 | AJ31: 1 | AO31: 1 | BD31: 1 | BF31: 1
A32: 30 | B32: Farmacias del Ahorro | C32: fahorro.com | D32: Farmacia | E32: Sí | F32: HTTP 200 | G32: Red (navegador) + HTML/GTM | H32: 13 | I32: GTM-P6QK8GFJ | J32: Retargeting a CPA/CPC (RTB House/Criteo/Smarterclick) | K32: 1 | L32: 1 | M32: 1 | P32: 1 | R32: 1 | T32: 1 | U32: 1 | AL32: 1 | BA32: 1 | BD32: 1 | BF32: 1 | BG32: 1 | CG32: 1
A33: 31 | B33: Farmacias Guadalajara | C33: farmaciasguadalajara.com | D33: Farmacia | E33: Sí | F33: BLOQUEADO · revisar en Chrome/Ghostery | H33: 0
A34: 32 | B34: Farmacias Benavides | C34: benavides.com.mx | D34: Farmacia | E34: No | F34: HTTP 200 | G34: Red (navegador) + HTML/GTM | H34: 10 | I34: GTM-NWNRF9Q | J34: Dynamic remarketing Google activo · MMP instalado (atribución app lista) | K34: 1 | L34: 1 | M34: 1 | V34: 1 | AG34: 1 | AL34: 1 | BD34: 1 | BF34: 1 | BJ34: 1 | CG34: 1
A35: 33 | B35: Farmacias San Pablo | C35: farmaciasanpablo.com.mx | D35: Farmacia | E35: No | F35: BLOQUEADO · revisar en Chrome/Ghostery | H35: 0
A36: 34 | B36: Farmacias Similares | C36: farmaciasdesimilares.com | D36: Farmacia | E36: No | F36: BLOQUEADO · revisar en Chrome/Ghostery | H36: 0
A37: 35 | B37: Sephora México | C37: sephora.com.mx | D37: Beauty | E37: Sí | F37: HTTP 403 · bloqueo bot (revisar en Chrome/Ghostery) | G37: Ghostery manual | H37: 9 | J37: Retargeting a CPA/CPC (RTB House/Criteo/Smarterclick) · Dynamic remarketing Google activo | K37: 1 | U37: 1 | V37: 1 | W37: 1 | AL37: 1 | AP37: 1 | AQ37: 1 | AW37: 1 | BD37: 1
A38: 36 | B38: Grisi | C38: grisi.com | D38: Beauty | E38: Sí | F38: HTTP 200 | G38: Red (navegador) + HTML/GTM | H38: 4 | I38: GTM-NLMWRGQP | K38: 1 | AL38: 1 | BD38: 1 | BF38: 1
A39: 37 | B39: Natura &Co (Natura / Avon) | C39: natura.com.mx | D39: Beauty | E39: No | F39: BLOQUEADO · revisar en Chrome/Ghostery | H39: 0
A40: 38 | B40: Mary Kay México | C40: marykay.com.mx | D40: Beauty | E40: No | F40: HTTP 200 | G40: Red (navegador) + HTML/GTM | H40: 7 | I40: GTM-TBN3TQR6 | K40: 1 | AL40: 1 | BD40: 1 | BF40: 1 | BO40: 1 | CF40: 1 | CJ40: 1
...

Sheet Detalle_Largo
A1: Empresa | B1: Dominio | C1: Categoría empresa | D1: En CRM | E1: Vendor / pixel | F1: Categoría vendor | G1: Método detección
A2: Mercado Libre | B2: mercadolibre.com.mx | C2: Marketplace | D2: Sí | E2: GA4 | F2: Analytics | G2: HTML/GTM
A3: Mercado Libre | B3: mercadolibre.com.mx | C3: Marketplace | D3: Sí | E3: Hotjar | F3: UX | G3: Red+HTML/GTM
A4: Mercado Libre | B4: mercadolibre.com.mx | C4: Marketplace | D4: Sí | E4: Contentsquare | F4: UX | G4: HTML/GTM
A5: Amazon México | B5: amazon.com.mx | C5: Marketplace | D5: Sí | E5: Contentsquare | F5: UX | G5: HTML/GTM
A6: Temu | B6: temu.com | C6: Marketplace | D6: No | E6: Google Ads / gtag | F6: Paid media | G6: HTML/GTM
A7: Temu | B7: temu.com | C7: Marketplace | D7: No | E7: Taboola | F7: Native | G7: HTML/GTM
A8: Temu | B8: temu.com | C8: Marketplace | D8: No | E8: GA4 | F8: Analytics | G8: HTML/GTM
A9: Shein | B9: shein.com.mx | C9: Marketplace | D9: No | E9: Google Ads / gtag | F9: Paid media | G9: HTML/GTM
A10: Shein | B10: shein.com.mx | C10: Marketplace | D10: No | E10: Awin | F10: Afiliados | G10: HTML/GTM
A11: Shein | B11: shein.com.mx | C11: Marketplace | D11: No | E11: Admitad | F11: Afiliados | G11: HTML/GTM
A12: Shein | B12: shein.com.mx | C12: Marketplace | D12: No | E12: GA4 | F12: Analytics | G12: HTML/GTM
... A765: Spin by OXXO (Femsa) | B765: spinbyoxxo.com.mx | C765: Fintech / BNPL / Wallet | D765: Sí | E765: Contentsquare | F765: UX | G765: HTML/GTM

Sheet Pendientes_Chrome_Ghostery
A1: Sitios que bloquearon el scan desde datacenter — revisar desde tu Chrome (IP residencial) con Ghostery o el snippet de consola
A2: # | B2: Empresa | C2: Dominio | D2: Categoría | E2: En CRM | F2: Estatus | G2: Hallazgo Ghostery (llenar) | H2: Fecha revisión
A3: 1 | B3: AliExpress | C3: aliexpress.com | D3: Marketplace | E3: No | F3: BLOQUEADO · revisar en Chrome/Ghostery
A4: 2 | B4: Sears México (Grupo Carso) | C4: sears.com.mx | D4: Departamental | E4: No | F4: BLOQUEADO · revisar en Chrome/Ghostery
A5: 3 | B5: Sanborns | C5: sanborns.com.mx | D5: Departamental | E5: No | F5: BLOQUEADO · revisar en Chrome/Ghostery
A6: 4 | B6: Walmart de México | C6: walmart.com.mx | D6: Autoservicio / Grocery | E6: Sí | F6: BLOQUEADO · revisar en Chrome/Ghostery
A7: 5 | B7: Chedraui | C7: chedraui.com.mx | D7: Autoservicio / Grocery | E7: Sí | F7: BLOQUEADO · revisar en Chrome/Ghostery
A8: 6 | B8: La Comer | C8: lacomer.com.mx | D8: Autoservicio / Grocery | E8: No | F8: BLOQUEADO · revisar en Chrome/Ghostery
A9: 7 | B9: Farmacias Guadalajara | C9: farmaciasguadalajara.com | D9: Farmacia | E9: Sí | F9: BLOQUEADO · revisar en Chrome/Ghostery
A10: 8 | B10: Farmacias San Pablo | C10: farmaciasanpablo.com.mx | D10: Farmacia | E10: No | F10: BLOQUEADO · revisar en Chrome/Ghostery
A11: 9 | B11: Farmacias Similares | C11: farmaciasdesimilares.com | D11: Farmacia | E11: No | F11: BLOQUEADO · revisar en Chrome/Ghostery
A12: 10 | B12: Natura &Co (Natura / Avon) | C12: natura.com.mx | D12: Beauty | E12: No | F12: BLOQUEADO · revisar en Chrome/Ghostery
A13: 11 | B13: Zara / Inditex México | C13: zara.com/mx | D13: Moda / Calzado | E13: No | F13: BLOQUEADO · revisar en Chrome/Ghostery
A14: 12 | B14: H&M México | C14: hm.com/mx | D14: Moda / Calzado | E14: No | F14: BLOQUEADO · revisar en Chrome/Ghostery
... A26: 24 | B26: Kavak | C26: kavak.com/mx | D26: Auto | E26: No | F26: BLOQUEADO · revisar en Chrome/Ghostery
A28: PROTOCOLO (3 min por sitio)
A29: 1. Abre el sitio en Chrome con Ghostery activo en modo 'Nunca bloquear' (solo observar), navega home → categoría → producto → carrito (sin comprar).
A30: 2. Abre el panel de Ghostery → pestaña 'Trackers detectados' → agrupa por categoría Advertising. Anota: RTB House, Criteo, Taboola, Outbrain, Teads, Seedtag, Adform, Xandr, TTD, AppsFlyer/Adjust/Branch, Awin/Impact/CJ/Rakuten/Admitad/Soicos.
A31: 3. Alternativa sin Ghostery — pega en DevTools > Console (F12) el snippet de abajo: lista todos los hosts de terceros cargados en la página actual.
A32: 4. Repite el snippet en la página de producto y en carrito: ahí disparan los pixeles de retargeting dinámico (RTB House/Criteo) que la home no siempre carga.
A33: 5. Pega los hallazgos en la columna 'Hallazgo Ghostery' de esta hoja y marca la fecha.
A35: SNIPPET DEVTOOLS (copia y pega en Console):
A36: (()=>{const h=new Set();performance.getEntriesByType('resource').forEach(e=>{try{h.add(new URL(e.name).hostname)}catch(_){}});const first=location.hostname.split('.').slice(-2).join('.');const out=[...h].filter(x=>!x.endsWith(first)).sort();copy(out.join('\n'));console.log(out.length+' hosts de terceros copiados al portapapeles:\n'+out.join('\n'));})();
A38: PROMPT PARA CLAUDE IN CHROME (ejecuta la lista bloqueada de arriba con tu sesión):
A39: Para cada dominio de la lista que te doy: abre la home, espera 8 segundos, haz scroll al final, entra a una página de producto cualquiera y agrégalo al carrito (no pagues). En cada una de las 3 páginas ejecuta en consola el snippet que te pego y guarda la salida. Al final entrégame una tabla: Dominio | Pixeles de paid media (Meta, Google Ads, TikTok, Pinterest, Snap, Bing) | Retargeting/CPA (RTB House, Criteo) | Native (Taboola, Outbrain) | Afiliados (Awin, Impact, CJ, Rakuten, Admitad, Soicos) | MMP (AppsFlyer, Adjust, Branch, Singular) | DMP/Identity (Retargetly, Lotame, LiveRamp, ID5) | Otros relevantes. No inventes: si un host no aparece en la salida de consola, no lo listes. Lista de dominios: [pegar columna C de esta hoja].

Sheet Benchmarks_CPA
A1: Benchmarks de CPA / CPI por categoría — fuentes públicas de terceros (NO son datos de LSIX)
A2: Uso: referencia para conversación de unit economics. El CPA real de cada anunciante sale de la sesión de unit economics (regla del playbook: nunca comprometer CPA sin ese dato). Cifras en USD.
A4: SUPUESTO (editable)
A5: CPM Meta México (USD) | B5: 3.92 | C5: Fuelads, Benchmarks LatAm Q2 2026 — https://fuelads.tech/benchmarks-latam-2026
A6: CPM Meta EE.UU. (USD) | B6: 16 | C6: Idem
A7: Factor de ajuste MX/US | B7: =B5/B6 -> 0.245
A8: Nota: el factor asume que el CPA escala con el CPM a igual tasa de conversión. Es una aproximación de Fuelads replicada aquí, no un benchmark medido en México. Úsalo como techo de conversación, no como precio.
A10: Categoría (Top100) | B10: Benchmark web más cercano | C10: CPA Meta mediana US (USD) | D10: CPA MX estimado (USD) = US × factor | E10: CPA Google Ads mediana US (USD) | F10: CPI app LatAm (USD, rango) | G10: Tipo de conversión CPA sugerida para LSIX | H10: Fuentes | I10: Confianza
A11: Marketplace | B11: E-commerce general | C11: 29.99 | D11: =IF(ISNUMBER(C11),C11*$B$7,"[PENDIENTE] sin benchmark de categoría") -> 7.34755 | E11: 23.74 | F11: 0.50–2.00 (shopping LatAm; Statista vía BoA: 1.42) | G11: Venta en app (% revenue o CPA fijo) | H11: Ryze AI, Meta Ads Cost Benchmarks by Industry 2026 (abr-2026) — https://www.get-ryze.ai/blog/cost-per-acquisition-benchmarks-2026; Business of Apps, App User Acquisition Costs 2025 (citando Sensor Tower, Adjust, Liftoff, AdAction) — https://www.businessofapps.com/marketplace/user-acquisition/research/user-acquisition-costs/ | I11: Media
A12: Departamental | B12: E-commerce general / Apparel | C12: 29.99 | D12: =IF(ISNUMBER(C12),C12*$B$7,"[PENDIENTE] sin benchmark de categoría") -> 7.34755 | E12: 23.74 | F12: 0.50–2.00 | G12: Venta en app; 1ª compra vs recurrente | H12: Ryze AI, Meta Ads Cost Benchmarks by Industry 2026 (abr-2026) — https://www.get-ryze.ai/blog/cost-per-acquisition-benchmarks-2026; Business of Apps, App User Acquisition Costs 2025 (citando Sensor Tower, Adjust, Liftoff, AdAction) — https://www.businessofapps.com/marketplace/user-acquisition/research/user-acquisition-costs/ | I12: Media
A13: Autoservicio / Grocery | B13: E-commerce general (sin benchmark grocery público) | C13: 29.99 | D13: =IF(ISNUMBER(C13),C13*$B$7,"[PENDIENTE] sin benchmark de categoría") -> 7.34755 | E13: 23.74 | F13: 0.50–2.00 | G13: Pedido en app (ticket bajo → CPA bajo, volumen) | H13: Ryze AI, Meta Ads Cost Benchmarks by Industry 2026 (abr-2026) — https://www.get-ryze.ai/blog/cost-per-acquisition-benchmarks-2026; Business of Apps, App User Acquisition Costs 2025 (citando Sensor Tower, Adjust, Liftoff, AdAction) — https://www.businessofapps.com/marketplace/user-acquisition/research/user-acquisition-costs/ | I13: Baja
A14: Delivery / QSR | B14: Food & Beverage (CPC más bajo 0.52; CPA sin dato público categoría) | C14: [PENDIENTE] | D14: =IF(ISNUMBER(C14),C14*$B$7,"[PENDIENTE] sin benchmark de categoría") -> [PENDIENTE] sin benchmark de categoría | E14: 23.74 | F14: 0.50–2.00 | G14: Primer pedido en app / pedido reactivado | H14: Ryze AI, Meta Ads Cost Benchmarks by Industry 2026 (abr-2026) — https://www.get-ryze.ai/blog/cost-per-acquisition-benchmarks-2026 (CPC); Business of Apps, App User Acquisition Costs 2025 (citando Sensor Tower, Adjust, Liftoff, AdAction) — https://www.businessofapps.com/marketplace/user-acquisition/research/user-acquisition-costs/ | I14: Baja
A15: Farmacia | B15: Health / e-commerce general | C15: 29.99 | D15: =IF(ISNUMBER(C15),C15*$B$7,"[PENDIENTE] sin benchmark de categoría") -> 7.34755 | E15: 23.74 | F15: 0.50–2.00 | G15: Venta en app; recurrencia (crónicos) | H15: Ryze AI, Meta Ads Cost Benchmarks by Industry 2026 (abr-2026) — https://www.get-ryze.ai/blog/cost-per-acquisition-benchmarks-2026; Business of Apps, App User Acquisition Costs 2025 (citando Sensor Tower, Adjust, Liftoff, AdAction) — https://www.businessofapps.com/marketplace/user-acquisition/research/user-acquisition-costs/ | I15: Baja
A16: Beauty | B16: Beauty & Cosmetics (CPL más bajo de la región según Fuelads) | C16: 29.99 | D16: =IF(ISNUMBER(C16),C16*$B$7,"[PENDIENTE] sin benchmark de categoría") -> 7.34755 | E16: 23.74 | F16: 0.50–2.00 | G16: Venta en app / 1ª compra | H16: Ryze AI, Meta Ads Cost Benchmarks by Industry 2026 (abr-2026) — https://www.get-ryze.ai/blog/cost-per-acquisition-benchmarks-2026; Fuelads Q2 2026 | I16: Media
A17: Moda / Calzado | B17: Apparel & Fashion (CPC más bajo: 0.45) | C17: 29.99 | D17: =IF(ISNUMBER(C17),C17*$B$7,"[PENDIENTE] sin benchmark de categoría") -> 7.34755 | E17: 23.74 | F17: 0.50–2.00 | G17: Venta en app; devolución como condición de validez | H17: Ryze AI, Meta Ads Cost Benchmarks by Industry 2026 (abr-2026) — https://www.get-ryze.ai/blog/cost-per-acquisition-benchmarks-2026; Business of Apps, App User Acquisition Costs 2025 (citando Sensor Tower, Adjust, Liftoff, AdAction) — https://www.businessofapps.com/marketplace/user-acquisition/research/user-acquisition-costs/ | I17: Media
A18: Deportes | B18: Apparel / Sporting goods | C18: 29.99 | D18: =IF(ISNUMBER(C18),C18*$B$7,"[PENDIENTE] sin benchmark de categoría") -> 7.34755 | E18: 23.74 | F18: 0.50–2.00 | G18: Venta en app; app install + 1ª compra (Innovasport) | H18: Ryze AI, Meta Ads Cost Benchmarks by Industry 2026 (abr-2026) — https://www.get-ryze.ai/blog/cost-per-acquisition-benchmarks-2026 | I18: Baja
A19: Electrónica / Tech | B19: Electronics (categoría más cara en Meta) | C19: 51.86 | D19: =IF(ISNUMBER(C19),C19*$B$7,"[PENDIENTE] sin benchmark de categoría") -> 12.7057 | E19: 23.74 | F19: 0.50–2.00 | G19: Venta en app (ticket alto → % revenue) | H19: Triple Whale, Facebook Ad Benchmarks (ago-2025→jul-2026, DTC/e-commerce) — https://www.triplewhale.com/blog/facebook-ads-benchmarks | I19: Media
A20: Hogar / Oficina / Variedad | B20: Home & Garden / e-commerce general | C20: 29.99 | D20: =IF(ISNUMBER(C20),C20*$B$7,"[PENDIENTE] sin benchmark de categoría") -> 7.34755 | E20: 23.74 | F20: 0.50–2.00 | G20: Venta en app; ticket alto → % revenue | H20: Ryze AI, Meta Ads Cost Benchmarks by Industry 2026 (abr-2026) — https://www.get-ryze.ai/blog/cost-per-acquisition-benchmarks-2026 | I20: Baja
A21: Travel / Movilidad | B21: Travel (sin CPA público por categoría; Triple Whale: Travel Accessories entre las más caras) | C21: [PENDIENTE] | D21: =IF(ISNUMBER(C21),C21*$B$7,"[PENDIENTE] sin benchmark de categoría") -> [PENDIENTE] sin benchmark de categoría | E21: 23.74 | F21: 0.50–2.00 | G21: Reserva/boleto emitido en app | H21: Triple Whale, Facebook Ad Benchmarks (ago-2025→jul-2026, DTC/e-commerce) — https://www.triplewhale.com/blog/facebook-ads-benchmarks; Business of Apps, App User Acquisition Costs 2025 (citando Sensor Tower, Adjust, Liftoff, AdAction) — https://www.businessofapps.com/marketplace/user-acquisition/research/user-acquisition-costs/ | I21: Baja
A22: Entretenimiento / Ticketing | B22: Entertainment (sin dato público) | C22: [PENDIENTE] | D22: =IF(ISNUMBER(C22),C22*$B$7,"[PENDIENTE] sin benchmark de categoría") -> [PENDIENTE] sin benchmark de categoría | E22: 23.74 | F22: 0.50–2.00 | G22: Boleto comprado en app | H22: Business of Apps, App User Acquisition Costs 2025 (citando Sensor Tower, Adjust, Liftoff, AdAction) — https://www.businessofapps.com/marketplace/user-acquisition/research/user-acquisition-costs/ | I22: Baja
A23: Auto | B23: Automotive (lead-based: CPL, no CPA) | C23: [PENDIENTE] | D23: =IF(ISNUMBER(C23),C23*$B$7,"[PENDIENTE] sin benchmark de categoría") -> [PENDIENTE] sin benchmark de categoría | E23: 23.74 | F23: n/a | G23: Lead calificado (CPL) / cita | H23: Ryze AI, Meta Ads Cost Benchmarks by Industry 2026 (abr-2026) — https://www.get-ryze.ai/blog/cost-per-acquisition-benchmarks-2026 | I23: Baja
A24: Nicho (mascotas, libros, juguetes, óptica, regalos) | B24: Books & Music 30.69 / Toys & Collectibles / Pets | C24: 30.69 | D24: =IF(ISNUMBER(C24),C24*$B$7,"[PENDIENTE] sin benchmark de categoría") -> 7.51905 | E24: 23.74 | F24: 0.50–2.00 | G24: Venta en app; suscripción (mascotas) | H24: Triple Whale, Facebook Ad Benchmarks (ago-2025→jul-2026, DTC/e-commerce) — https://www.triplewhale.com/blog/facebook-ads-benchmarks | I24: Media
A25: Fintech / BNPL / Wallet | B25: Finance (CPI más alto: 2.50–6.00 global; BoA 8.23) | C25: [PENDIENTE] | D25: =IF(ISNUMBER(C25),C25*$B$7,"[PENDIENTE] sin benchmark de categoría") -> [PENDIENTE] sin benchmark de categoría | E25: 23.74 | F25: 2.50–6.00 (global, Adjust/Juniper 2024); LatAm menor — sin dato público MX | G25: Alta/KYC completada, 1ª transacción, crédito desembolsado (CPA por evento, no por install) | H25: Business of Apps, App User Acquisition Costs 2025 (citando Sensor Tower, Adjust, Liftoff, AdAction) — https://www.businessofapps.com/marketplace/user-acquisition/research/user-acquisition-costs/; Insert Affiliate, Mobile App UA Cost Benchmarks (may-2026) — https://insertaffiliate.com/blog/mobile-app-user-acquisition-cost-benchmarks/ | I25: Media
A26: Telco | B26: Telecom (sin CPA público) | C26: [PENDIENTE] | D26: =IF(ISNUMBER(C26),C26*$B$7,"[PENDIENTE] sin benchmark de categoría") -> [PENDIENTE] sin benchmark de categoría | E26: 23.74 | F26: 0.50–2.00 | G26: Alta de línea / portabilidad / recarga en app | H26: Business of Apps, App User Acquisition Costs 2025 (citando Sensor Tower, Adjust, Liftoff, AdAction) — https://www.businessofapps.com/marketplace/user-acquisition/research/user-acquisition-costs/ | I26: Baja
A28: Referencias transversales: CPA mediana Meta todas las industrias US 2026 = $38.19 (Ryze); Triple Whale ago-25→jul-26 = $38.99, ROAS mediana 1.88, CVR 1.53%; CPA Google Ads mediana US 2026 = $23.74 (Ryze); Q4 cuesta 30–40% más que Q1 (Fuelads).
A29: Lo que NO existe públicamente: CPA por anunciante en México. Ese dato solo sale de (a) la sesión de unit economics, (b) el margen/LTV que comparta el cliente, (c) la pregunta de discovery '¿ya compran a CPA con afiliados/redes y a qué precio?' (playbook slide 6).
A30: Los sitios con Awin/Impact/CJ/Admitad/Soicos en la Matriz_Pixeles ya pagan CPA a afiliados: en discovery pide el payout de su programa — es el benchmark real del anunciante y el techo de tu negociación.
A31: Los sitios con RTB House o Criteo ya compran retargeting a CPC/CPA con garantía: el pitch de LSIX compite directamente en ese presupuesto, no en el fee del holding.
